tested:
    Indention Errors
    --------------------------------------------------------------------------
    Many IndentationError exceptions now have more context regarding what kind
    of block was expecting an indentation, including the location of the
    statement

run:
    python indention_error_run.py

expected:
    test_with_if (indention_error_tests.GeneralTest)
    Testing that many IndentationError exceptions now have more context ... ok
    test_with_while (indention_error_tests.GeneralTest)
    Testing that many IndentationError exceptions now have more context ... ok

    ----------------------------------------------------------------------
    Ran 2 tests in 0.001s

    OK

Cpython:
    test_with_if (indention_error_tests.GeneralTest)
    Testing that many IndentationError exceptions now have more context ... ok
    test_with_while (indention_error_tests.GeneralTest)
    Testing that many IndentationError exceptions now have more context ... ok

    ----------------------------------------------------------------------
    Ran 2 tests in 0.001s

    OK

Pypy:
    test_with_if (indention_error_tests.GeneralTest)
    Testing that many IndentationError exceptions now have more context ... FAIL
    test_with_while (indention_error_tests.GeneralTest)
    Testing that many IndentationError exceptions now have more context ... FAIL

    ======================================================================
    FAIL: test_with_if (indention_error_tests.GeneralTest)
    Testing that many IndentationError exceptions now have more context
    ----------------------------------------------------------------------
      File "<string>", line 2
        x=5
        ^
    IndentationError: expected an indented block

    During handling of the above exception, another exception occurred:

    Traceback (most recent call last):
      File "/home/sasha_pavlov/Work_mb/Pavlov_testtask/pythonProject/New Features/error_messages_tests/indention_error_tests/indention_error_tests.py", line 12, in test_with_if
        compile("if True:\nx=5", "", "exec")
    AssertionError: ".*expected an indented block after 'if" does not match "expected an indented block (, line 2)"

    ======================================================================
    FAIL: test_with_while (indention_error_tests.GeneralTest)
    Testing that many IndentationError exceptions now have more context
    ----------------------------------------------------------------------
      File "<string>", line 2
        x=5
        ^
    IndentationError: expected an indented block

    During handling of the above exception, another exception occurred:

    Traceback (most recent call last):
      File "/home/sasha_pavlov/Work_mb/Pavlov_testtask/pythonProject/New Features/error_messages_tests/indention_error_tests/indention_error_tests.py", line 20, in test_with_while
        compile("while True:\nx=5", "", "exec")
    AssertionError: ".*expected an indented block after 'while'" does not match "expected an indented block (, line 2)"

    ----------------------------------------------------------------------
    Ran 2 tests in 0.001s

    FAILED (failures=2)